<?xml version="1.0" encoding="utf-8"?>
<!-- This URDF was automatically created by SolidWorks to URDF Exporter! Originally created by Stephen Brawner (brawner@gmail.com) 
     Commit Version: 1.5.1-0-g916b5db  Build Version: 1.5.7152.31018
     For more information, please see http://wiki.ros.org/sw_urdf_exporter -->
<robot
  name="assembledtwo">
  <link
    name="base_link">
    <inertial>
      <origin
        xyz="-0.029652 -0.29014 0.14653"
        rpy="0 0 0" />
      <mass
        value="0.43373" />
      <inertia
        ixx="0.00040447"
        ixy="-9.1851E-12"
        ixz="4.4606E-07"
        iyy="0.00043971"
        iyz="2.0884E-12"
        izz="0.00018319" />
    </inertial>
    <visual>
      <origin
        xyz="0 0 0"
        rpy="0 0 0" />
      <geometry>
        <mesh
          filename="package://assembledtwo/meshes/base_link.STL" />
      </geometry>
      <material
        name="ABS">
        <color
          rgba="0.79216 0.81961 0.93333 1" />
      </material>
    </visual>
    <collision>
      <origin
        xyz="0 0 0"
        rpy="0 0 0" />
      <geometry>
        <mesh
          filename="package://assembledtwo/meshes/base_link.STL" />
      </geometry>
    </collision>
  </link>
  <link
    name="First_link">
    <inertial>
      <origin
        xyz="-0.00022485 0.075247 -0.027124"
        rpy="0 0 0" />
      <mass
        value="0.32355" />
      <inertia
        ixx="0.00038047"
        ixy="-2.8639E-06"
        ixz="-7.5251E-10"
        iyy="0.0001506"
        iyz="1.591E-09"
        izz="0.00041126" />
    </inertial>
    <visual>
      <origin
        xyz="0 0 0"
        rpy="0 0 0" />
      <geometry>
        <mesh
          filename="package://assembledtwo/meshes/First_link.STL" />
      </geometry>
      <material
        name="ABS">
        <color
          rgba="0.79216 0.81961 0.93333 1" />
      </material>
    </visual>
    <collision>
      <origin
        xyz="0 0 0"
        rpy="0 0 0" />
      <geometry>
        <mesh
          filename="package://assembledtwo/meshes/First_link.STL" />
      </geometry>
    </collision>
  </link>
  <joint
    name="rev1"
    type="revolute">
    <origin
      xyz="0 -0.29014 0.2643"
      rpy="1.5708 -0.024407 1.5708" />
    <parent
      link="base_link" />
    <child
      link="First_link" />
    <axis
      xyz="0 0 1" />
    <limit
      lower="-1.571"
      upper="1.571"
      effort="0"
      velocity="0" />
  </joint>
  <link
    name="Second_link">
    <inertial>
      <origin
        xyz="-0.034341 3.4054E-05 0.0024757"
        rpy="0 0 0" />
      <mass
        value="0.1211" />
      <inertia
        ixx="6.2831E-05"
        ixy="-1.5813E-06"
        ixz="-1.1967E-07"
        iyy="0.00013324"
        iyz="-1.5058E-09"
        izz="9.5648E-05" />
    </inertial>
    <visual>
      <origin
        xyz="0 0 0"
        rpy="0 0 0" />
      <geometry>
        <mesh
          filename="package://assembledtwo/meshes/Second_link.STL" />
      </geometry>
      <material
        name="ABS">
        <color
          rgba="0.96471 0.96471 0.95294 1" />
      </material>
    </visual>
    <collision>
      <origin
        xyz="0 0 0"
        rpy="0 0 0" />
      <geometry>
        <mesh
          filename="package://assembledtwo/meshes/Second_link.STL" />
      </geometry>
    </collision>
  </link>
  <joint
    name="rev2"
    type="revolute">
    <origin
      xyz="0 0.16 -0.027124"
      rpy="-1.5708 -0.012065 -1.5708" />
    <parent
      link="First_link" />
    <child
      link="Second_link" />
    <axis
      xyz="0 0 1" />
    <limit
      lower="-1.571"
      upper="1.571"
      effort="0"
      velocity="0" />
  </joint>
  <link
    name="Third_link">
    <inertial>
      <origin
        xyz="0.00039817 0.00517 -0.048976"
        rpy="0 0 0" />
      <mass
        value="0.16034" />
      <inertia
        ixx="0.0002664"
        ixy="-7.9729E-09"
        ixz="1.114E-06"
        iyy="0.00019515"
        iyz="1.1835E-06"
        izz="8.7881E-05" />
    </inertial>
    <visual>
      <origin
        xyz="0 0 0"
        rpy="0 0 0" />
      <geometry>
        <mesh
          filename="package://assembledtwo/meshes/Third_link.STL" />
      </geometry>
      <material
        name="ABS">
        <color
          rgba="0.79216 0.81961 0.93333 1" />
      </material>
    </visual>
    <collision>
      <origin
        xyz="0 0 0"
        rpy="0 0 0" />
      <geometry>
        <mesh
          filename="package://assembledtwo/meshes/Third_link.STL" />
      </geometry>
    </collision>
  </link>
  <joint
    name="rev3"
    type="revolute">
    <origin
      xyz="-0.075 -0.0004747 0"
      rpy="1.5708 0 1.7261" />
    <parent
      link="Second_link" />
    <child
      link="Third_link" />
    <axis
      xyz="0 1 0" />
    <limit
      lower="-1.571"
      upper="1.571"
      effort="0"
      velocity="0" />
  </joint>
</robot>